Workbook

Sheet Inputs
A1: O9010 — Torus Groove Contour Validator V3
A2: Edit blue cells only. GCode tab generates automatically.
A4: Parameter | B4: Value | C4: Units
A5: I — XY circle radius (tool centerline) | B5: 1.165 | C5: inches
A6: J — XZ minor arc radius | B6: 5.197 | C6: inches
A7: DIR — direction +1=CCW / -1=CW | B7: 1
A8: Xctr — center X | B8: 0 | C8: inches
A9: Yctr — center Y | B9: 0 | C9: inches
A10: Step — angular increment (degrees) | B10: 1 | C10: degrees
A11: R — retract plane Z | B11: 1 | C11: inches
A12: S — spindle speed | B12: 1200 | C12: RPM
A13: F — feed rate (IPM) | B13: 8 | C13: IPM
A14: H — tool length offset number | B14: 1
A16: Derived values
A17: XY diameter (2×I) | B17: =2*B5 -> 2.33 | C17: inches
A18: Half-subtended angle ASIN(I/J) | B18: =DEGREES(ASIN(B5/B6)) -> 12.953946 | C18: degrees
A19: Max B tilt = half subtended | B19: =DEGREES(ASIN(B5/B6)) -> 12.953946 | C19: degrees
A20: Max Z depth | B20: =-B6*(1-COS(RADIANS(DEGREES(ASIN(B5/B6))))) -> -0.13226072 | C20: inches
A21: Total Z excursion | B21: =ABS(2*B6*(1-COS(RADIANS(DEGREES(ASIN(B5/B6)))))) -> 0.26452143 | C21: inches
A22: Contour steps (360/Step) | B22: =360/B10 -> 360 | C22: blocks
A24: Geometry: phi=ASIN(I*SIN(C)/J) — correct for I<>J.

Sheet Data
A1: C (deg) | B1: Theta (deg) | C1: phi (deg) | D1: X (in.) | E1: Y (in.) | F1: Z (in.) | G1: B (deg) | H1: R_check (in.)
A2: =0*Inputs!$B$10*Inputs!$B$7 -> 0 | B2: =0*Inputs!$B$10 -> 0 | C2: =DEGREES(ASIN(MIN(MAX(Inputs!$B$5/Inputs!$B$6*SIN(RADIANS(A2)),-1),1))) -> 0 | D2: =Inputs!$B$8+Inputs!$B$5*COS(RADIANS(A2)) -> 1.165 | E2: =Inputs!$B$9+Inputs!$B$5*SIN(RADIANS(A2)) -> 0 | F2: =-Inputs!$B$6*(1-COS(RADIANS(C2))) -> 0 | G2: =C2*Inputs!$B$7 -> 0 | H2: =SQRT(D2^2+E2^2) -> 1.165
A3: =1*Inputs!$B$10*Inputs!$B$7 -> 1 | B3: =1*Inputs!$B$10 -> 1 | C3: =DEGREES(ASIN(MIN(MAX(Inputs!$B$5/Inputs!$B$6*SIN(RADIANS(A3)),-1),1))) -> 0.22415698 | D3: =Inputs!$B$8+Inputs!$B$5*COS(RADIANS(A3)) -> 1.1648226 | E3: =Inputs!$B$9+Inputs!$B$5*SIN(RADIANS(A3)) -> 0.020332053 | F3: =-Inputs!$B$6*(1-COS(RADIANS(C3))) -> -3.9772367e-05 | G3: =C3*Inputs!$B$7 -> 0.22415698 | H3: =SQRT(D3^2+E3^2) -> 1.165
A4: =2*Inputs!$B$10*Inputs!$B$7 -> 2 | B4: =2*Inputs!$B$10 -> 2 | C4: =DEGREES(ASIN(MIN(MAX(Inputs!$B$5/Inputs!$B$6*SIN(RADIANS(A4)),-1),1))) -> 0.44824911 | D4: =Inputs!$B$8+Inputs!$B$5*COS(RADIANS(A4)) -> 1.1642903 | E4: =Inputs!$B$9+Inputs!$B$5*SIN(RADIANS(A4)) -> 0.040657914 | F4: =-Inputs!$B$6*(1-COS(RADIANS(C4))) -> -0.00015904284 | G4: =C4*Inputs!$B$7 -> 0.44824911 | H4: =SQRT(D4^2+E4^2) -> 1.165
A5: =3*Inputs!$B$10*Inputs!$B$7 -> 3 | B5: =3*Inputs!$B$10 -> 3 | C5: =DEGREES(ASIN(MIN(MAX(Inputs!$B$5/Inputs!$B$6*SIN(RADIANS(A5)),-1),1))) -> 0.67221155 | D5: =Inputs!$B$8+Inputs!$B$5*COS(RADIANS(A5)) -> 1.1634034 | E5: =Inputs!$B$9+Inputs!$B$5*SIN(RADIANS(A5)) -> 0.060971389 | F5: =-Inputs!$B$6*(1-COS(RADIANS(C5))) -> -0.00035767156 | G5: =C5*Inputs!$B$7 -> 0.67221155 | H5: =SQRT(D5^2+E5^2) -> 1.165
A6: =4*Inputs!$B$10*Inputs!$B$7 -> 4 | B6: =4*Inputs!$B$10 -> 4 | C6: =DEGREES(ASIN(MIN(MAX(Inputs!$B$5/Inputs!$B$6*SIN(RADIANS(A6)),-1),1))) -> 0.89597947 | D6: =Inputs!$B$8+Inputs!$B$5*COS(RADIANS(A6)) -> 1.1621621 | E6: =Inputs!$B$9+Inputs!$B$5*SIN(RADIANS(A6)) -> 0.081266292 | F6: =-Inputs!$B$6*(1-COS(RADIANS(C6))) -> -0.00063542563 | G6: =C6*Inputs!$B$7 -> 0.89597947 | H6: =SQRT(D6^2+E6^2) -> 1.165
A7: =5*Inputs!$B$10*Inputs!$B$7 -> 5 | B7: =5*Inputs!$B$10 -> 5 | C7: =DEGREES(ASIN(MIN(MAX(Inputs!$B$5/Inputs!$B$6*SIN(RADIANS(A7)),-1),1))) -> 1.1194881 | D7: =Inputs!$B$8+Inputs!$B$5*COS(RADIANS(A7)) -> 1.1605668 | E7: =Inputs!$B$9+Inputs!$B$5*SIN(RADIANS(A7)) -> 0.10153644 | F7: =-Inputs!$B$6*(1-COS(RADIANS(C7))) -> -0.00099197929 | G7: =C7*Inputs!$B$7 -> 1.1194881 | H7: =SQRT(D7^2+E7^2) -> 1.165
A8: =6*Inputs!$B$10*Inputs!$B$7 -> 6 | B8: =6*Inputs!$B$10 -> 6 | C8: =DEGREES(ASIN(MIN(MAX(Inputs!$B$5/Inputs!$B$6*SIN(RADIANS(A8)),-1),1))) -> 1.3426727 | D8: =Inputs!$B$8+Inputs!$B$5*COS(RADIANS(A8)) -> 1.158618 | E8: =Inputs!$B$9+Inputs!$B$5*SIN(RADIANS(A8)) -> 0.12177566 | F8: =-Inputs!$B$6*(1-COS(RADIANS(C8))) -> -0.0014269143 | G8: =C8*Inputs!$B$7 -> 1.3426727 | H8: =SQRT(D8^2+E8^2) -> 1.165
A9: =7*Inputs!$B$10*Inputs!$B$7 -> 7 | B9: =7*Inputs!$B$10 -> 7 | C9: =DEGREES(ASIN(MIN(MAX(Inputs!$B$5/Inputs!$B$6*SIN(RADIANS(A9)),-1),1))) -> 1.5654686 | D9: =Inputs!$B$8+Inputs!$B$5*COS(RADIANS(A9)) -> 1.1563163 | E9: =Inputs!$B$9+Inputs!$B$5*SIN(RADIANS(A9)) -> 0.14197779 | F9: =-Inputs!$B$6*(1-COS(RADIANS(C9))) -> -0.0019397204 | G9: =C9*Inputs!$B$7 -> 1.5654686 | H9: =SQRT(D9^2+E9^2) -> 1.165
A10: =8*Inputs!$B$10*Inputs!$B$7 -> 8 | B10: =8*Inputs!$B$10 -> 8 | C10: =DEGREES(ASIN(MIN(MAX(Inputs!$B$5/Inputs!$B$6*SIN(RADIANS(A10)),-1),1))) -> 1.7878111 | D10: =Inputs!$B$8+Inputs!$B$5*COS(RADIANS(A10)) -> 1.1536623 | E10: =Inputs!$B$9+Inputs!$B$5*SIN(RADIANS(A10)) -> 0.16213666 | F10: =-Inputs!$B$6*(1-COS(RADIANS(C10))) -> -0.0025297958 | G10: =C10*Inputs!$B$7 -> 1.7878111 | H10: =SQRT(D10^2+E10^2) -> 1.165
A11: =9*Inputs!$B$10*Inputs!$B$7 -> 9 | B11: =9*Inputs!$B$10 -> 9 | C11: =DEGREES(ASIN(MIN(MAX(Inputs!$B$5/Inputs!$B$6*SIN(RADIANS(A11)),-1),1))) -> 2.0096357 | D11: =Inputs!$B$8+Inputs!$B$5*COS(RADIANS(A11)) -> 1.1506569 | E11: =Inputs!$B$9+Inputs!$B$5*SIN(RADIANS(A11)) -> 0.18224615 | F11: =-Inputs!$B$6*(1-COS(RADIANS(C11))) -> -0.0031964477 | G11: =C11*Inputs!$B$7 -> 2.0096357 | H11: =SQRT(D11^2+E11^2) -> 1.165
A12: =10*Inputs!$B$10*Inputs!$B$7 -> 10 | B12: =10*Inputs!$B$10 -> 10 | C12: =DEGREES(ASIN(MIN(MAX(Inputs!$B$5/Inputs!$B$6*SIN(RADIANS(A12)),-1),1))) -> 2.2308779 | D12: =Inputs!$B$8+Inputs!$B$5*COS(RADIANS(A12)) -> 1.147301 | E12: =Inputs!$B$9+Inputs!$B$5*SIN(RADIANS(A12)) -> 0.20230013 | F12: =-Inputs!$B$6*(1-COS(RADIANS(C12))) -> -0.0039388932 | G12: =C12*Inputs!$B$7 -> 2.2308779 | H12: =SQRT(D12^2+E12^2) -> 1.165
A13: =11*Inputs!$B$10*Inputs!$B$7 -> 11 | B13: =11*Inputs!$B$10 -> 11 | C13: =DEGREES(ASIN(MIN(MAX(Inputs!$B$5/Inputs!$B$6*SIN(RADIANS(A13)),-1),1))) -> 2.4514735 | D13: =Inputs!$B$8+Inputs!$B$5*COS(RADIANS(A13)) -> 1.1435957 | E13: =Inputs!$B$9+Inputs!$B$5*SIN(RADIANS(A13)) -> 0.22229248 | F13: =-Inputs!$B$6*(1-COS(RADIANS(C13))) -> -0.0047562602 | G13: =C13*Inputs!$B$7 -> 2.4514735 | H13: =SQRT(D13^2+E13^2) -> 1.165
A14: =12*Inputs!$B$10*Inputs!$B$7 -> 12 | B14: =12*Inputs!$B$10 -> 12 | C14: =DEGREES(ASIN(MIN(MAX(Inputs!$B$5/Inputs!$B$6*SIN(RADIANS(A14)),-1),1))) -> 2.6713581 | D14: =Inputs!$B$8+Inputs!$B$5*COS(RADIANS(A14)) -> 1.139542 | E14: =Inputs!$B$9+Inputs!$B$5*SIN(RADIANS(A14)) -> 0.24221712 | F14: =-Inputs!$B$6*(1-COS(RADIANS(C14))) -> -0.0056475879 | G14: =C14*Inputs!$B$7 -> 2.6713581 | H14: =SQRT(D14^2+E14^2) -> 1.165
A15: =13*Inputs!$B$10*Inputs!$B$7 -> 13 | B15: =13*Inputs!$B$10 -> 13 | C15: =DEGREES(ASIN(MIN(MAX(Inputs!$B$5/Inputs!$B$6*SIN(RADIANS(A15)),-1),1))) -> 2.8904676 | D15: =Inputs!$B$8+Inputs!$B$5*COS(RADIANS(A15)) -> 1.1351411 | E15: =Inputs!$B$9+Inputs!$B$5*SIN(RADIANS(A15)) -> 0.26206798 | F15: =-Inputs!$B$6*(1-COS(RADIANS(C15))) -> -0.0066118281 | G15: =C15*Inputs!$B$7 -> 2.8904676 | H15: =SQRT(D15^2+E15^2) -> 1.165
A16: =14*Inputs!$B$10*Inputs!$B$7 -> 14 | B16: =14*Inputs!$B$10 -> 14 | C16: =DEGREES(ASIN(MIN(MAX(Inputs!$B$5/Inputs!$B$6*SIN(RADIANS(A16)),-1),1))) -> 3.108738 | D16: =Inputs!$B$8+Inputs!$B$5*COS(RADIANS(A16)) -> 1.1303945 | E16: =Inputs!$B$9+Inputs!$B$5*SIN(RADIANS(A16)) -> 0.28183901 | F16: =-Inputs!$B$6*(1-COS(RADIANS(C16))) -> -0.0076478465 | G16: =C16*Inputs!$B$7 -> 3.108738 | H16: =SQRT(D16^2+E16^2) -> 1.165
A17: =15*Inputs!$B$10*Inputs!$B$7 -> 15 | B17: =15*Inputs!$B$10 -> 15 | C17: =DEGREES(ASIN(MIN(MAX(Inputs!$B$5/Inputs!$B$6*SIN(RADIANS(A17)),-1),1))) -> 3.3261055 | D17: =Inputs!$B$8+Inputs!$B$5*COS(RADIANS(A17)) -> 1.1253036 | E17: =Inputs!$B$9+Inputs!$B$5*SIN(RADIANS(A17)) -> 0.30152419 | F17: =-Inputs!$B$6*(1-COS(RADIANS(C17))) -> -0.0087544233 | G17: =C17*Inputs!$B$7 -> 3.3261055 | H17: =SQRT(D17^2+E17^2) -> 1.165
A18: =16*Inputs!$B$10*Inputs!$B$7 -> 16 | B18: =16*Inputs!$B$10 -> 16 | C18: =DEGREES(ASIN(MIN(MAX(Inputs!$B$5/Inputs!$B$6*SIN(RADIANS(A18)),-1),1))) -> 3.5425065 | D18: =Inputs!$B$8+Inputs!$B$5*COS(RADIANS(A18)) -> 1.1198699 | E18: =Inputs!$B$9+Inputs!$B$5*SIN(RADIANS(A18)) -> 0.32111752 | F18: =-Inputs!$B$6*(1-COS(RADIANS(C18))) -> -0.0099302551 | G18: =C18*Inputs!$B$7 -> 3.5425065 | H18: =SQRT(D18^2+E18^2) -> 1.165
A19: =17*Inputs!$B$10*Inputs!$B$7 -> 17 | B19: =17*Inputs!$B$10 -> 17 | C19: =DEGREES(ASIN(MIN(MAX(Inputs!$B$5/Inputs!$B$6*SIN(RADIANS(A19)),-1),1))) -> 3.7578773 | D19: =Inputs!$B$8+Inputs!$B$5*COS(RADIANS(A19)) -> 1.114095 | E19: =Inputs!$B$9+Inputs!$B$5*SIN(RADIANS(A19)) -> 0.34061304 | F19: =-Inputs!$B$6*(1-COS(RADIANS(C19))) -> -0.011173956 | G19: =C19*Inputs!$B$7 -> 3.7578773 | H19: =SQRT(D19^2+E19^2) -> 1.165
A20: =18*Inputs!$B$10*Inputs!$B$7 -> 18 | B20: =18*Inputs!$B$10 -> 18 | C20: =DEGREES(ASIN(MIN(MAX(Inputs!$B$5/Inputs!$B$6*SIN(RADIANS(A20)),-1),1))) -> 3.9721547 | D20: =Inputs!$B$8+Inputs!$B$5*COS(RADIANS(A20)) -> 1.1079808 | E20: =Inputs!$B$9+Inputs!$B$5*SIN(RADIANS(A20)) -> 0.3600048 | F20: =-Inputs!$B$6*(1-COS(RADIANS(C20))) -> -0.012484059 | G20: =C20*Inputs!$B$7 -> 3.9721547 | H20: =SQRT(D20^2+E20^2) -> 1.165
A21: =19*Inputs!$B$10*Inputs!$B$7 -> 19 | B21: =19*Inputs!$B$10 -> 19 | C21: =DEGREES(ASIN(MIN(MAX(Inputs!$B$5/Inputs!$B$6*SIN(RADIANS(A21)),-1),1))) -> 4.1852755 | D21: =Inputs!$B$8+Inputs!$B$5*COS(RADIANS(A21)) -> 1.1015291 | E21: =Inputs!$B$9+Inputs!$B$5*SIN(RADIANS(A21)) -> 0.3792869 | F21: =-Inputs!$B$6*(1-COS(RADIANS(C21))) -> -0.013859017 | G21: =C21*Inputs!$B$7 -> 4.1852755 | H21: =SQRT(D21^2+E21^2) -> 1.165
A22: =20*Inputs!$B$10*Inputs!$B$7 -> 20 | B22: =20*Inputs!$B$10 -> 20 | C22: =DEGREES(ASIN(MIN(MAX(Inputs!$B$5/Inputs!$B$6*SIN(RADIANS(A22)),-1),1))) -> 4.3971768 | D22: =Inputs!$B$8+Inputs!$B$5*COS(RADIANS(A22)) -> 1.0947419 | E22: =Inputs!$B$9+Inputs!$B$5*SIN(RADIANS(A22)) -> 0.39845347 | F22: =-Inputs!$B$6*(1-COS(RADIANS(C22))) -> -0.015297207 | G22: =C22*Inputs!$B$7 -> 4.3971768 | H22: =SQRT(D22^2+E22^2) -> 1.165
A23: =21*Inputs!$B$10*Inputs!$B$7 -> 21 | B23: =21*Inputs!$B$10 -> 21 | C23: =DEGREES(ASIN(MIN(MAX(Inputs!$B$5/Inputs!$B$6*SIN(RADIANS(A23)),-1),1))) -> 4.607796 | D23: =Inputs!$B$8+Inputs!$B$5*COS(RADIANS(A23)) -> 1.0876212 | E23: =Inputs!$B$9+Inputs!$B$5*SIN(RADIANS(A23)) -> 0.41749866 | F23: =-Inputs!$B$6*(1-COS(RADIANS(C23))) -> -0.016796928 | G23: =C23*Inputs!$B$7 -> 4.607796 | H23: =SQRT(D23^2+E23^2) -> 1.165
A24: =22*Inputs!$B$10*Inputs!$B$7 -> 22 | B24: =22*Inputs!$B$10 -> 22 | C24: =DEGREES(ASIN(MIN(MAX(Inputs!$B$5/Inputs!$B$6*SIN(RADIANS(A24)),-1),1))) -> 4.8170705 | D24: =Inputs!$B$8+Inputs!$B$5*COS(RADIANS(A24)) -> 1.0801692 | E24: =Inputs!$B$9+Inputs!$B$5*SIN(RADIANS(A24)) -> 0.43641668 | F24: =-Inputs!$B$6*(1-COS(RADIANS(C24))) -> -0.018356405 | G24: =C24*Inputs!$B$7 -> 4.8170705 | H24: =SQRT(D24^2+E24^2) -> 1.165
A25: =23*Inputs!$B$10*Inputs!$B$7 -> 23 | B25: =23*Inputs!$B$10 -> 23 | C25: =DEGREES(ASIN(MIN(MAX(Inputs!$B$5/Inputs!$B$6*SIN(RADIANS(A25)),-1),1))) -> 5.0249383 | D25: =Inputs!$B$8+Inputs!$B$5*COS(RADIANS(A25)) -> 1.0723882 | E25: =Inputs!$B$9+Inputs!$B$5*SIN(RADIANS(A25)) -> 0.45520176 | F25: =-Inputs!$B$6*(1-COS(RADIANS(C25))) -> -0.019973792 | G25: =C25*Inputs!$B$7 -> 5.0249383 | H25: =SQRT(D25^2+E25^2) -> 1.165
A26: =24*Inputs!$B$10*Inputs!$B$7 -> 24 | B26: =24*Inputs!$B$10 -> 24 | C26: =DEGREES(ASIN(MIN(MAX(Inputs!$B$5/Inputs!$B$6*SIN(RADIANS(A26)),-1),1))) -> 5.2313373 | D26: =Inputs!$B$8+Inputs!$B$5*COS(RADIANS(A26)) -> 1.0642805 | E26: =Inputs!$B$9+Inputs!$B$5*SIN(RADIANS(A26)) -> 0.47384819 | F26: =-Inputs!$B$6*(1-COS(RADIANS(C26))) -> -0.021647172 | G26: =C26*Inputs!$B$7 -> 5.2313373 | H26: =SQRT(D26^2+E26^2) -> 1.165
A27: =25*Inputs!$B$10*Inputs!$B$7 -> 25 | B27: =25*Inputs!$B$10 -> 25 | C27: =DEGREES(ASIN(MIN(MAX(Inputs!$B$5/Inputs!$B$6*SIN(RADIANS(A27)),-1),1))) -> 5.4362059 | D27: =Inputs!$B$8+Inputs!$B$5*COS(RADIANS(A27)) -> 1.0558486 | E27: =Inputs!$B$9+Inputs!$B$5*SIN(RADIANS(A27)) -> 0.49235027 | F27: =-Inputs!$B$6*(1-COS(RADIANS(C27))) -> -0.023374559 | G27: =C27*Inputs!$B$7 -> 5.4362059 | H27: =SQRT(D27^2+E27^2) -> 1.165
A28: =26*Inputs!$B$10*Inputs!$B$7 -> 26 | B28: =26*Inputs!$B$10 -> 26 | C28: =DEGREES(ASIN(MIN(MAX(Inputs!$B$5/Inputs!$B$6*SIN(RADIANS(A28)),-1),1))) -> 5.6394827 | D28: =Inputs!$B$8+Inputs!$B$5*COS(RADIANS(A28)) -> 1.0470951 | E28: =Inputs!$B$9+Inputs!$B$5*SIN(RADIANS(A28)) -> 0.51070239 | F28: =-Inputs!$B$6*(1-COS(RADIANS(C28))) -> -0.025153901 | G28: =C28*Inputs!$B$7 -> 5.6394827 | H28: =SQRT(D28^2+E28^2) -> 1.165
A29: =27*Inputs!$B$10*Inputs!$B$7 -> 27 | B29: =27*Inputs!$B$10 -> 27 | C29: =DEGREES(ASIN(MIN(MAX(Inputs!$B$5/Inputs!$B$6*SIN(RADIANS(A29)),-1),1))) -> 5.8411068 | D29: =Inputs!$B$8+Inputs!$B$5*COS(RADIANS(A29)) -> 1.0380226 | E29: =Inputs!$B$9+Inputs!$B$5*SIN(RADIANS(A29)) -> 0.52889893 | F29: =-Inputs!$B$6*(1-COS(RADIANS(C29))) -> -0.026983083 | G29: =C29*Inputs!$B$7 -> 5.8411068 | H29: =SQRT(D29^2+E29^2) -> 1.165
A30: =28*Inputs!$B$10*Inputs!$B$7 -> 28 | B30: =28*Inputs!$B$10 -> 28 | C30: =DEGREES(ASIN(MIN(MAX(Inputs!$B$5/Inputs!$B$6*SIN(RADIANS(A30)),-1),1))) -> 6.0410173 | D30: =Inputs!$B$8+Inputs!$B$5*COS(RADIANS(A30)) -> 1.0286339 | E30: =Inputs!$B$9+Inputs!$B$5*SIN(RADIANS(A30)) -> 0.54693437 | F30: =-Inputs!$B$6*(1-COS(RADIANS(C30))) -> -0.028859929 | G30: =C30*Inputs!$B$7 -> 6.0410173 | H30: =SQRT(D30^2+E30^2) -> 1.165
A31: =29*Inputs!$B$10*Inputs!$B$7 -> 29 | B31: =29*Inputs!$B$10 -> 29 | C31: =DEGREES(ASIN(MIN(MAX(Inputs!$B$5/Inputs!$B$6*SIN(RADIANS(A31)),-1),1))) -> 6.2391541 | D31: =Inputs!$B$8+Inputs!$B$5*COS(RADIANS(A31)) -> 1.018932 | E31: =Inputs!$B$9+Inputs!$B$5*SIN(RADIANS(A31)) -> 0.56480321 | F31: =-Inputs!$B$6*(1-COS(RADIANS(C31))) -> -0.030782202 | G31: =C31*Inputs!$B$7 -> 6.2391541 | H31: =SQRT(D31^2+E31^2) -> 1.165
A32: =30*Inputs!$B$10*Inputs!$B$7 -> 30 | B32: =30*Inputs!$B$10 -> 30 | C32: =DEGREES(ASIN(MIN(MAX(Inputs!$B$5/Inputs!$B$6*SIN(RADIANS(A32)),-1),1))) -> 6.4354569 | D32: =Inputs!$B$8+Inputs!$B$5*COS(RADIANS(A32)) -> 1.0089196 | E32: =Inputs!$B$9+Inputs!$B$5*SIN(RADIANS(A32)) -> 0.5825 | F32: =-Inputs!$B$6*(1-COS(RADIANS(C32))) -> -0.03274761 | G32: =C32*Inputs!$B$7 -> 6.4354569 | H32: =SQRT(D32^2+E32^2) -> 1.165
A33: =31*Inputs!$B$10*Inputs!$B$7 -> 31 | B33: =31*Inputs!$B$10 -> 31 | C33: =DEGREES(ASIN(MIN(MAX(Inputs!$B$5/Inputs!$B$6*SIN(RADIANS(A33)),-1),1))) -> 6.6298664 | D33: =Inputs!$B$8+Inputs!$B$5*COS(RADIANS(A33)) -> 0.99859991 | E33: =Inputs!$B$9+Inputs!$B$5*SIN(RADIANS(A33)) -> 0.60001936 | F33: =-Inputs!$B$6*(1-COS(RADIANS(C33))) -> -0.034753806 | G33: =C33*Inputs!$B$7 -> 6.6298664 | H33: =SQRT(D33^2+E33^2) -> 1.165
A34: =32*Inputs!$B$10*Inputs!$B$7 -> 32 | B34: =32*Inputs!$B$10 -> 32 | C34: =DEGREES(ASIN(MIN(MAX(Inputs!$B$5/Inputs!$B$6*SIN(RADIANS(A34)),-1),1))) -> 6.8223231 | D34: =Inputs!$B$8+Inputs!$B$5*COS(RADIANS(A34)) -> 0.98797603 | E34: =Inputs!$B$9+Inputs!$B$5*SIN(RADIANS(A34)) -> 0.61735594 | F34: =-Inputs!$B$6*(1-COS(RADIANS(C34))) -> -0.036798392 | G34: =C34*Inputs!$B$7 -> 6.8223231 | H34: =SQRT(D34^2+E34^2) -> 1.165
A35: =33*Inputs!$B$10*Inputs!$B$7 -> 33 | B35: =33*Inputs!$B$10 -> 33 | C35: =DEGREES(ASIN(MIN(MAX(Inputs!$B$5/Inputs!$B$6*SIN(RADIANS(A35)),-1),1))) -> 7.0127683 | D35: =Inputs!$B$8+Inputs!$B$5*COS(RADIANS(A35)) -> 0.97705121 | E35: =Inputs!$B$9+Inputs!$B$5*SIN(RADIANS(A35)) -> 0.63450448 | F35: =-Inputs!$B$6*(1-COS(RADIANS(C35))) -> -0.038878921 | G35: =C35*Inputs!$B$7 -> 7.0127683 | H35: =SQRT(D35^2+E35^2) -> 1.165
A36: =34*Inputs!$B$10*Inputs!$B$7 -> 34 | B36: =34*Inputs!$B$10 -> 34 | C36: =DEGREES(ASIN(MIN(MAX(Inputs!$B$5/Inputs!$B$6*SIN(RADIANS(A36)),-1),1))) -> 7.2011437 | D36: =Inputs!$B$8+Inputs!$B$5*COS(RADIANS(A36)) -> 0.96582877 | E36: =Inputs!$B$9+Inputs!$B$5*SIN(RADIANS(A36)) -> 0.65145973 | F36: =-Inputs!$B$6*(1-COS(RADIANS(C36))) -> -0.0409929 | G36: =C36*Inputs!$B$7 -> 7.2011437 | H36: =SQRT(D36^2+E36^2) -> 1.165
A37: =35*Inputs!$B$10*Inputs!$B$7 -> 35 | B37: =35*Inputs!$B$10 -> 35 | C37: =DEGREES(ASIN(MIN(MAX(Inputs!$B$5/Inputs!$B$6*SIN(RADIANS(A37)),-1),1))) -> 7.3873912 | D37: =Inputs!$B$8+Inputs!$B$5*COS(RADIANS(A37)) -> 0.95431213 | E37: =Inputs!$B$9+Inputs!$B$5*SIN(RADIANS(A37)) -> 0.66821655 | F37: =-Inputs!$B$6*(1-COS(RADIANS(C37))) -> -0.043137793 | G37: =C37*Inputs!$B$7 -> 7.3873912 | H37: =SQRT(D37^2+E37^2) -> 1.165
A38: =36*Inputs!$B$10*Inputs!$B$7 -> 36 | B38: =36*Inputs!$B$10 -> 36 | C38: =DEGREES(ASIN(MIN(MAX(Inputs!$B$5/Inputs!$B$6*SIN(RADIANS(A38)),-1),1))) -> 7.5714535 | D38: =Inputs!$B$8+Inputs!$B$5*COS(RADIANS(A38)) -> 0.9425048 | E38: =Inputs!$B$9+Inputs!$B$5*SIN(RADIANS(A38)) -> 0.68476982 | F38: =-Inputs!$B$6*(1-COS(RADIANS(C38))) -> -0.045311025 | G38: =C38*Inputs!$B$7 -> 7.5714535 | H38: =SQRT(D38^2+E38^2) -> 1.165
A39: =37*Inputs!$B$10*Inputs!$B$7 -> 37 | B39: =37*Inputs!$B$10 -> 37 | C39: =DEGREES(ASIN(MIN(MAX(Inputs!$B$5/Inputs!$B$6*SIN(RADIANS(A39)),-1),1))) -> 7.7532736 | D39: =Inputs!$B$8+Inputs!$B$5*COS(RADIANS(A39)) -> 0.93041037 | E39: =Inputs!$B$9+Inputs!$B$5*SIN(RADIANS(A39)) -> 0.7011145 | F39: =-Inputs!$B$6*(1-COS(RADIANS(C39))) -> -0.047509981 | G39: =C39*Inputs!$B$7 -> 7.7532736 | H39: =SQRT(D39^2+E39^2) -> 1.165
A40: =38*Inputs!$B$10*Inputs!$B$7 -> 38 | B40: =38*Inputs!$B$10 -> 38 | C40: =DEGREES(ASIN(MIN(MAX(Inputs!$B$5/Inputs!$B$6*SIN(RADIANS(A40)),-1),1))) -> 7.932795 | D40: =Inputs!$B$8+Inputs!$B$5*COS(RADIANS(A40)) -> 0.91803253 | E40: =Inputs!$B$9+Inputs!$B$5*SIN(RADIANS(A40)) -> 0.71724562 | F40: =-Inputs!$B$6*(1-COS(RADIANS(C40))) -> -0.049732014 | G40: =C40*Inputs!$B$7 -> 7.932795 | H40: =SQRT(D40^2+E40^2) -> 1.165
...

Sheet GCode
A1: O9010 — Generated G-Code
A2: Each row = one block. Each cell = one word. Positive values have no sign.
A3: N | B3: G/M | C3: X | D3: Y | E3: Z | F3: B | G3: C | H3: F / S / H
A4: (PREAMBLE) | B4: G20 | C4: G90 | D4: G94
B5: G49
B6: G00 | F6: B0.0000 | G6: C0.0000 | H6: =CONCATENATE("Z",TEXT(Inputs!B11,"0.0000")) -> Z1.0000
B7: G00 | C7: =CONCATENATE("X",TEXT(ABS(Inputs!B8+Inputs!B5),"0.0000")) -> X1.1650 | D7: =CONCATENATE("Y",TEXT(ABS(Inputs!B9),"0.0000")) -> Y0.0000
B8: G234 | H8: =CONCATENATE("H",TEXT(Inputs!B14,"0")) -> H1
B9: M03 | H9: =CONCATENATE("S",TEXT(Inputs!B12,"0")) -> S1200
B10: G00 | C10: =CONCATENATE("X",TEXT(ABS(Inputs!B8+Inputs!B5),"0.0000")) -> X1.1650 | D10: =CONCATENATE("Y",TEXT(ABS(Inputs!B9),"0.0000")) -> Y0.0000 | E10: =CONCATENATE("Z",TEXT(Inputs!B11,"0.0000")) -> Z1.0000 | F10: B0.0000 | G10: C0.0000
B11: G01 | C11: =CONCATENATE("X",TEXT(ABS(Inputs!B8+Inputs!B5),"0.0000")) -> X1.1650 | D11: =CONCATENATE("Y",TEXT(ABS(Inputs!B9),"0.0000")) -> Y0.0000 | E11: Z0.0000 | F11: B0.0000 | G11: C0.0000 | H11: =CONCATENATE("F",TEXT(Inputs!B13,"0.0")) -> F8.0
A12: (CONTOUR)
A13: N1 | B13: G01 | C13: =CONCATENATE("X",IF(Data!D2<0,"-",""),TEXT(ABS(Data!D2),"0.0000")) -> X1.1650 | D13: =CONCATENATE("Y",IF(Data!E2<0,"-",""),TEXT(ABS(Data!E2),"0.0000")) -> Y0.0000 | E13: =CONCATENATE("Z",IF(Data!F2<0,"-",""),TEXT(ABS(Data!F2),"0.0000")) -> Z0.0000 | F13: =CONCATENATE("B",IF(Data!G2<0,"-",""),TEXT(ABS(Data!G2),"0.0000")) -> B0.0000 | G13: =CONCATENATE("C",IF(Data!A2<0,"-",""),TEXT(ABS(Data!A2),"0.0000")) -> C0.0000
A14: N2 | B14: G01 | C14: =CONCATENATE("X",IF(Data!D3<0,"-",""),TEXT(ABS(Data!D3),"0.0000")) -> X1.1648 | D14: =CONCATENATE("Y",IF(Data!E3<0,"-",""),TEXT(ABS(Data!E3),"0.0000")) -> Y0.0203 | E14: =CONCATENATE("Z",IF(Data!F3<0,"-",""),TEXT(ABS(Data!F3),"0.0000")) -> Z-0.0000 | F14: =CONCATENATE("B",IF(Data!G3<0,"-",""),TEXT(ABS(Data!G3),"0.0000")) -> B0.2242 | G14: =CONCATENATE("C",IF(Data!A3<0,"-",""),TEXT(ABS(Data!A3),"0.0000")) -> C1.0000
A15: N3 | B15: G01 | C15: =CONCATENATE("X",IF(Data!D4<0,"-",""),TEXT(ABS(Data!D4),"0.0000")) -> X1.1643 | D15: =CONCATENATE("Y",IF(Data!E4<0,"-",""),TEXT(ABS(Data!E4),"0.0000")) -> Y0.0407 | E15: =CONCATENATE("Z",IF(Data!F4<0,"-",""),TEXT(ABS(Data!F4),"0.0000")) -> Z-0.0002 | F15: =CONCATENATE("B",IF(Data!G4<0,"-",""),TEXT(ABS(Data!G4),"0.0000")) -> B0.4482 | G15: =CONCATENATE("C",IF(Data!A4<0,"-",""),TEXT(ABS(Data!A4),"0.0000")) -> C2.0000
A16: N4 | B16: G01 | C16: =CONCATENATE("X",IF(Data!D5<0,"-",""),TEXT(ABS(Data!D5),"0.0000")) -> X1.1634 | D16: =CONCATENATE("Y",IF(Data!E5<0,"-",""),TEXT(ABS(Data!E5),"0.0000")) -> Y0.0610 | E16: =CONCATENATE("Z",IF(Data!F5<0,"-",""),TEXT(ABS(Data!F5),"0.0000")) -> Z-0.0004 | F16: =CONCATENATE("B",IF(Data!G5<0,"-",""),TEXT(ABS(Data!G5),"0.0000")) -> B0.6722 | G16: =CONCATENATE("C",IF(Data!A5<0,"-",""),TEXT(ABS(Data!A5),"0.0000")) -> C3.0000
A17: N5 | B17: G01 | C17: =CONCATENATE("X",IF(Data!D6<0,"-",""),TEXT(ABS(Data!D6),"0.0000")) -> X1.1622 | D17: =CONCATENATE("Y",IF(Data!E6<0,"-",""),TEXT(ABS(Data!E6),"0.0000")) -> Y0.0813 | E17: =CONCATENATE("Z",IF(Data!F6<0,"-",""),TEXT(ABS(Data!F6),"0.0000")) -> Z-0.0006 | F17: =CONCATENATE("B",IF(Data!G6<0,"-",""),TEXT(ABS(Data!G6),"0.0000")) -> B0.8960 | G17: =CONCATENATE("C",IF(Data!A6<0,"-",""),TEXT(ABS(Data!A6),"0.0000")) -> C4.0000
A18: N6 | B18: G01 | C18: =CONCATENATE("X",IF(Data!D7<0,"-",""),TEXT(ABS(Data!D7),"0.0000")) -> X1.1606 | D18: =CONCATENATE("Y",IF(Data!E7<0,"-",""),TEXT(ABS(Data!E7),"0.0000")) -> Y0.1015 | E18: =CONCATENATE("Z",IF(Data!F7<0,"-",""),TEXT(ABS(Data!F7),"0.0000")) -> Z-0.0010 | F18: =CONCATENATE("B",IF(Data!G7<0,"-",""),TEXT(ABS(Data!G7),"0.0000")) -> B1.1195 | G18: =CONCATENATE("C",IF(Data!A7<0,"-",""),TEXT(ABS(Data!A7),"0.0000")) -> C5.0000
A19: N7 | B19: G01 | C19: =CONCATENATE("X",IF(Data!D8<0,"-",""),TEXT(ABS(Data!D8),"0.0000")) -> X1.1586 | D19: =CONCATENATE("Y",IF(Data!E8<0,"-",""),TEXT(ABS(Data!E8),"0.0000")) -> Y0.1218 | E19: =CONCATENATE("Z",IF(Data!F8<0,"-",""),TEXT(ABS(Data!F8),"0.0000")) -> Z-0.0014 | F19: =CONCATENATE("B",IF(Data!G8<0,"-",""),TEXT(ABS(Data!G8),"0.0000")) -> B1.3427 | G19: =CONCATENATE("C",IF(Data!A8<0,"-",""),TEXT(ABS(Data!A8),"0.0000")) -> C6.0000
A20: N8 | B20: G01 | C20: =CONCATENATE("X",IF(Data!D9<0,"-",""),TEXT(ABS(Data!D9),"0.0000")) -> X1.1563 | D20: =CONCATENATE("Y",IF(Data!E9<0,"-",""),TEXT(ABS(Data!E9),"0.0000")) -> Y0.1420 | E20: =CONCATENATE("Z",IF(Data!F9<0,"-",""),TEXT(ABS(Data!F9),"0.0000")) -> Z-0.0019 | F20: =CONCATENATE("B",IF(Data!G9<0,"-",""),TEXT(ABS(Data!G9),"0.0000")) -> B1.5655 | G20: =CONCATENATE("C",IF(Data!A9<0,"-",""),TEXT(ABS(Data!A9),"0.0000")) -> C7.0000
A21: N9 | B21: G01 | C21: =CONCATENATE("X",IF(Data!D10<0,"-",""),TEXT(ABS(Data!D10),"0.0000")) -> X1.1537 | D21: =CONCATENATE("Y",IF(Data!E10<0,"-",""),TEXT(ABS(Data!E10),"0.0000")) -> Y0.1621 | E21: =CONCATENATE("Z",IF(Data!F10<0,"-",""),TEXT(ABS(Data!F10),"0.0000")) -> Z-0.0025 | F21: =CONCATENATE("B",IF(Data!G10<0,"-",""),TEXT(ABS(Data!G10),"0.0000")) -> B1.7878 | G21: =CONCATENATE("C",IF(Data!A10<0,"-",""),TEXT(ABS(Data!A10),"0.0000")) -> C8.0000
A22: N10 | B22: G01 | C22: =CONCATENATE("X",IF(Data!D11<0,"-",""),TEXT(ABS(Data!D11),"0.0000")) -> X1.1507 | D22: =CONCATENATE("Y",IF(Data!E11<0,"-",""),TEXT(ABS(Data!E11),"0.0000")) -> Y0.1822 | E22: =CONCATENATE("Z",IF(Data!F11<0,"-",""),TEXT(ABS(Data!F11),"0.0000")) -> Z-0.0032 | F22: =CONCATENATE("B",IF(Data!G11<0,"-",""),TEXT(ABS(Data!G11),"0.0000")) -> B2.0096 | G22: =CONCATENATE("C",IF(Data!A11<0,"-",""),TEXT(ABS(Data!A11),"0.0000")) -> C9.0000
A23: N11 | B23: G01 | C23: =CONCATENATE("X",IF(Data!D12<0,"-",""),TEXT(ABS(Data!D12),"0.0000")) -> X1.1473 | D23: =CONCATENATE("Y",IF(Data!E12<0,"-",""),TEXT(ABS(Data!E12),"0.0000")) -> Y0.2023 | E23: =CONCATENATE("Z",IF(Data!F12<0,"-",""),TEXT(ABS(Data!F12),"0.0000")) -> Z-0.0039 | F23: =CONCATENATE("B",IF(Data!G12<0,"-",""),TEXT(ABS(Data!G12),"0.0000")) -> B2.2309 | G23: =CONCATENATE("C",IF(Data!A12<0,"-",""),TEXT(ABS(Data!A12),"0.0000")) -> C10.0000
A24: N12 | B24: G01 | C24: =CONCATENATE("X",IF(Data!D13<0,"-",""),TEXT(ABS(Data!D13),"0.0000")) -> X1.1436 | D24: =CONCATENATE("Y",IF(Data!E13<0,"-",""),TEXT(ABS(Data!E13),"0.0000")) -> Y0.2223 | E24: =CONCATENATE("Z",IF(Data!F13<0,"-",""),TEXT(ABS(Data!F13),"0.0000")) -> Z-0.0048 | F24: =CONCATENATE("B",IF(Data!G13<0,"-",""),TEXT(ABS(Data!G13),"0.0000")) -> B2.4515 | G24: =CONCATENATE("C",IF(Data!A13<0,"-",""),TEXT(ABS(Data!A13),"0.0000")) -> C11.0000
... A373: N361 | B373: G01 | C373: =CONCATENATE("X",IF(Data!D362<0,"-",""),TEXT(ABS(Data!D362),"0.0000")) -> X1.1650 | D373: =CONCATENATE("Y",IF(Data!E362<0,"-",""),TEXT(ABS(Data!E362),"0.0000")) -> Y-0.0000 | E373: =CONCATENATE("Z",IF(Data!F362<0,"-",""),TEXT(ABS(Data!F362),"0.0000")) -> Z0.0000 | F373: =CONCATENATE("B",IF(Data!G362<0,"-",""),TEXT(ABS(Data!G362),"0.0000")) -> B-0.0000 | G373: =CONCATENATE("C",IF(Data!A362<0,"-",""),TEXT(ABS(Data!A362),"0.0000")) -> C360.0000
A374: (RETRACT) | B374: G49
B375: G00 | E375: =CONCATENATE("Z",TEXT(Inputs!B11,"0.0000")) -> Z1.0000
B376: G00 | F376: B0.0000 | G376: C0.0000
B377: G43 | H377: =CONCATENATE("H",TEXT(Inputs!B14,"0")) -> H1
B378: M99

Sheet XY Plot
A1: Tool Path — XY Plane
A2: Single clean circle = correct

Sheet XZ Plot
A1: Z Profile vs C Angle
A2: Smooth saddle 0->deep->0 = correct

Sheet Phi Plot
A1: Phi vs C Angle
A2: Peak = ASIN(I/J) = correct

Sheet B Tilt Plot
A1: B Axis Tilt vs C Angle
A2: Sinusoid bounded by ASIN(I/J)

Sheet Radius Check
A1: Radius Check (flat = correct)
A2: Flat line at I = no XY error
